// src/components/error/GlobalErrorBoundary.tsx
"use client";

import React, { Component, ErrorInfo, ReactNode } from "react";
import { logClientError, ErrorSeverity } from "@/lib/error-logger";
import ErrorFallback from "./ErrorFallback";

interface Props {
  children: ReactNode;
  fallback?: ReactNode;
  onError?: (error: Error, errorInfo: ErrorInfo) => void;
}

interface State {
  hasError: boolean;
  error: Error | null;
  errorId: string | null;
  retryCount: number;
}

export default class GlobalErrorBoundary extends Component<Props, State> {
  private retryTimeoutId: NodeJS.Timeout | null = null;

  constructor(props: Props) {
    super(props);

    this.state = {
      hasError: false,
      error: null,
      errorId: null,
      retryCount: 0,
    };
  }

  static getDerivedStateFromError(error: Error): Partial<State> {
    // Update state so the next render will show the fallback UI
    return {
      hasError: true,
      error,
    };
  }

  async componentDidCatch(error: Error, errorInfo: ErrorInfo) {
    // Log the error
    try {
      const errorLog = await logClientError(error, {
        componentStack: errorInfo.componentStack,
        errorBoundary: true,
        retryCount: this.state.retryCount,
        userAgent: typeof window !== "undefined" ? navigator.userAgent : undefined,
        url: typeof window !== "undefined" ? window.location.href : undefined,
        timestamp: new Date(),
      });

      this.setState({ errorId: errorLog.id });

      // Call custom error handler if provided
      this.props.onError?.(error, errorInfo);

      // Log to console for development
      if (process.env.NODE_ENV === "development") {
        console.group("ðŸš¨ Error Boundary Caught Error");
        console.error("Error:", error);
        console.error("Error Info:", errorInfo);
        console.error("Component Stack:", errorInfo.componentStack);
        console.groupEnd();
      }
    } catch (loggingError) {
      console.error("Failed to log error:", loggingError);
    }
  }

  handleRetry = () => {
    this.setState(prevState => ({
      hasError: false,
      error: null,
      errorId: null,
      retryCount: prevState.retryCount + 1,
    }));
  };

  handleReload = () => {
    if (typeof window !== "undefined") {
      window.location.reload();
    }
  };

  componentWillUnmount() {
    if (this.retryTimeoutId) {
      clearTimeout(this.retryTimeoutId);
    }
  }

  render() {
    if (this.state.hasError) {
      // If custom fallback is provided, use it
      if (this.props.fallback) {
        return this.props.fallback;
      }

      // Use default error fallback
      return (
        <ErrorFallback
          error={this.state.error}
          errorId={this.state.errorId}
          onRetry={this.handleRetry}
          onReload={this.handleReload}
          retryCount={this.state.retryCount}
        />
      );
    }

    return this.props.children;
  }
}

// Hook for manual error reporting
export function useErrorHandler() {
  return React.useCallback(async (error: Error | unknown, context?: any) => {
    try {
      await logClientError(error, {
        manual: true,
        context,
        timestamp: new Date(),
      });
    } catch (loggingError) {
      console.error("Failed to log manual error:", loggingError);
    }
  }, []);
}

// Higher-order component for wrapping components with error boundary
export function withErrorBoundary<P extends object>(
  Component: React.ComponentType<P>,
  errorFallback?: ReactNode
) {
  const WrappedComponent = (props: P) => {
    return (
      <GlobalErrorBoundary fallback={errorFallback}>
        <Component {...props} />
      </GlobalErrorBoundary>
    );
  };

  WrappedComponent.displayName = `withErrorBoundary(${Component.displayName || Component.name})`;
  
  return WrappedComponent;
}